root@mousum-IdeaPad-Gaming-3-15IHU6:/# colcon build
Traceback (most recent call last):
  File "<string>", line 1, in <module>
  File "/usr/lib/python3/dist-packages/setuptools/_distutils/core.py", line 267, in run_setup
    exec(code, g)
  File "<string>", line 9, in <module>
ModuleNotFoundError: No module named 'numpy.distutils'
[0.516s] ERROR:colcon.colcon_core.package_identification:Exception in package identification extension 'python_setup_py' in 'lib/python3/dist-packages/numpy/_typing': Command '['/usr/bin/python3', '-c', 'import sys;from contextlib import suppress;exec("with suppress(ImportError):    from setuptools.extern.packaging.specifiers    import SpecifierSet");exec("with suppress(ImportError):    from packaging.specifiers import SpecifierSet");from distutils.core import run_setup;dist = run_setup(    \'setup.py\', script_args=(\'--dry-run\',), stop_after=\'config\');skip_keys = (\'cmdclass\', \'distclass\', \'ext_modules\', \'metadata\');data = {    key: value for key, value in dist.__dict__.items()     if (        not key.startswith(\'_\') and         not callable(value) and         key not in skip_keys and         key not in dist.display_option_names    )};data[\'metadata\'] = {    k: v for k, v in dist.metadata.__dict__.items()     if k not in (\'license_files\', \'provides_extras\')};sys.stdout.buffer.write(repr(data).encode(\'utf-8\'))']' returned non-zero exit status 1.
Traceback (most recent call last):
  File "/usr/lib/python3/dist-packages/colcon_core/package_identification/__init__.py", line 144, in _identify
    retval = extension.identify(_reused_descriptor_instance)
             ^^^^^^^^^^^^^^^^^^^^^^^^^^^^^^^^^^^^^^^^^^^^^^^
  File "/usr/lib/python3/dist-packages/colcon_python_setup_py/package_identification/python_setup_py.py", line 48, in identify
    config = get_setup_information(setup_py)
             ^^^^^^^^^^^^^^^^^^^^^^^^^^^^^^^
  File "/usr/lib/python3/dist-packages/colcon_python_setup_py/package_identification/python_setup_py.py", line 249, in get_setup_information
    _setup_information_cache[hashable_env] = _get_setup_information(
                                             ^^^^^^^^^^^^^^^^^^^^^^^
  File "/usr/lib/python3/dist-packages/colcon_python_setup_py/package_identification/python_setup_py.py", line 296, in _get_setup_information
    result = subprocess.run(
             ^^^^^^^^^^^^^^^
  File "/usr/lib/python3.12/subprocess.py", line 571, in run
    raise CalledProcessError(retcode, process.args,
subprocess.CalledProcessError: Command '['/usr/bin/python3', '-c', 'import sys;from contextlib import suppress;exec("with suppress(ImportError):    from setuptools.extern.packaging.specifiers    import SpecifierSet");exec("with suppress(ImportError):    from packaging.specifiers import SpecifierSet");from distutils.core import run_setup;dist = run_setup(    \'setup.py\', script_args=(\'--dry-run\',), stop_after=\'config\');skip_keys = (\'cmdclass\', \'distclass\', \'ext_modules\', \'metadata\');data = {    key: value for key, value in dist.__dict__.items()     if (        not key.startswith(\'_\') and         not callable(value) and         key not in skip_keys and         key not in dist.display_option_names    )};data[\'metadata\'] = {    k: v for k, v in dist.metadata.__dict__.items()     if k not in (\'license_files\', \'provides_extras\')};sys.stdout.buffer.write(repr(data).encode(\'utf-8\'))']' returned non-zero exit status 1.

Traceback (most recent call last):
  File "<string>", line 1, in <module>
  File "/usr/lib/python3/dist-packages/setuptools/_distutils/core.py", line 267, in run_setup
    exec(code, g)
  File "<string>", line 10, in <module>
ModuleNotFoundError: No module named 'numpy.distutils'
[0.667s] ERROR:colcon.colcon_core.package_identification:Exception in package identification extension 'python_setup_py' in 'lib/python3/dist-packages/numpy/array_api': Command '['/usr/bin/python3', '-c', 'import sys;from contextlib import suppress;exec("with suppress(ImportError):    from setuptools.extern.packaging.specifiers    import SpecifierSet");exec("with suppress(ImportError):    from packaging.specifiers import SpecifierSet");from distutils.core import run_setup;dist = run_setup(    \'setup.py\', script_args=(\'--dry-run\',), stop_after=\'config\');skip_keys = (\'cmdclass\', \'distclass\', \'ext_modules\', \'metadata\');data = {    key: value for key, value in dist.__dict__.items()     if (        not key.startswith(\'_\') and         not callable(value) and         key not in skip_keys and         key not in dist.display_option_names    )};data[\'metadata\'] = {    k: v for k, v in dist.metadata.__dict__.items()     if k not in (\'license_files\', \'provides_extras\')};sys.stdout.buffer.write(repr(data).encode(\'utf-8\'))']' returned non-zero exit status 1.
Traceback (most recent call last):
  File "/usr/lib/python3/dist-packages/colcon_core/package_identification/__init__.py", line 144, in _identify
    retval = extension.identify(_reused_descriptor_instance)
             ^^^^^^^^^^^^^^^^^^^^^^^^^^^^^^^^^^^^^^^^^^^^^^^
  File "/usr/lib/python3/dist-packages/colcon_python_setup_py/package_identification/python_setup_py.py", line 48, in identify
    config = get_setup_information(setup_py)
             ^^^^^^^^^^^^^^^^^^^^^^^^^^^^^^^
  File "/usr/lib/python3/dist-packages/colcon_python_setup_py/package_identification/python_setup_py.py", line 249, in get_setup_information
    _setup_information_cache[hashable_env] = _get_setup_information(
                                             ^^^^^^^^^^^^^^^^^^^^^^^
  File "/usr/lib/python3/dist-packages/colcon_python_setup_py/package_identification/python_setup_py.py", line 296, in _get_setup_information
    result = subprocess.run(
             ^^^^^^^^^^^^^^^
  File "/usr/lib/python3.12/subprocess.py", line 571, in run
    raise CalledProcessError(retcode, process.args,
subprocess.CalledProcessError: Command '['/usr/bin/python3', '-c', 'import sys;from contextlib import suppress;exec("with suppress(ImportError):    from setuptools.extern.packaging.specifiers    import SpecifierSet");exec("with suppress(ImportError):    from packaging.specifiers import SpecifierSet");from distutils.core import run_setup;dist = run_setup(    \'setup.py\', script_args=(\'--dry-run\',), stop_after=\'config\');skip_keys = (\'cmdclass\', \'distclass\', \'ext_modules\', \'metadata\');data = {    key: value for key, value in dist.__dict__.items()     if (        not key.startswith(\'_\') and         not callable(value) and         key not in skip_keys and         key not in dist.display_option_names    )};data[\'metadata\'] = {    k: v for k, v in dist.metadata.__dict__.items()     if k not in (\'license_files\', \'provides_extras\')};sys.stdout.buffer.write(repr(data).encode(\'utf-8\'))']' returned non-zero exit status 1.

Traceback (most recent call last):
  File "<string>", line 1, in <module>
  File "/usr/lib/python3/dist-packages/setuptools/_distutils/core.py", line 267, in run_setup
    exec(code, g)
  File "<string>", line 9, in <module>
ModuleNotFoundError: No module named 'numpy.distutils'
[0.812s] ERROR:colcon.colcon_core.package_identification:Exception in package identification extension 'python_setup_py' in 'lib/python3/dist-packages/numpy/compat': Command '['/usr/bin/python3', '-c', 'import sys;from contextlib import suppress;exec("with suppress(ImportError):    from setuptools.extern.packaging.specifiers    import SpecifierSet");exec("with suppress(ImportError):    from packaging.specifiers import SpecifierSet");from distutils.core import run_setup;dist = run_setup(    \'setup.py\', script_args=(\'--dry-run\',), stop_after=\'config\');skip_keys = (\'cmdclass\', \'distclass\', \'ext_modules\', \'metadata\');data = {    key: value for key, value in dist.__dict__.items()     if (        not key.startswith(\'_\') and         not callable(value) and         key not in skip_keys and         key not in dist.display_option_names    )};data[\'metadata\'] = {    k: v for k, v in dist.metadata.__dict__.items()     if k not in (\'license_files\', \'provides_extras\')};sys.stdout.buffer.write(repr(data).encode(\'utf-8\'))']' returned non-zero exit status 1.
Traceback (most recent call last):
  File "/usr/lib/python3/dist-packages/colcon_core/package_identification/__init__.py", line 144, in _identify
    retval = extension.identify(_reused_descriptor_instance)
             ^^^^^^^^^^^^^^^^^^^^^^^^^^^^^^^^^^^^^^^^^^^^^^^
  File "/usr/lib/python3/dist-packages/colcon_python_setup_py/package_identification/python_setup_py.py", line 48, in identify
    config = get_setup_information(setup_py)
             ^^^^^^^^^^^^^^^^^^^^^^^^^^^^^^^
  File "/usr/lib/python3/dist-packages/colcon_python_setup_py/package_identification/python_setup_py.py", line 249, in get_setup_information
    _setup_information_cache[hashable_env] = _get_setup_information(
                                             ^^^^^^^^^^^^^^^^^^^^^^^
  File "/usr/lib/python3/dist-packages/colcon_python_setup_py/package_identification/python_setup_py.py", line 296, in _get_setup_information
    result = subprocess.run(
             ^^^^^^^^^^^^^^^
  File "/usr/lib/python3.12/subprocess.py", line 571, in run
    raise CalledProcessError(retcode, process.args,
subprocess.CalledProcessError: Command '['/usr/bin/python3', '-c', 'import sys;from contextlib import suppress;exec("with suppress(ImportError):    from setuptools.extern.packaging.specifiers    import SpecifierSet");exec("with suppress(ImportError):    from packaging.specifiers import SpecifierSet");from distutils.core import run_setup;dist = run_setup(    \'setup.py\', script_args=(\'--dry-run\',), stop_after=\'config\');skip_keys = (\'cmdclass\', \'distclass\', \'ext_modules\', \'metadata\');data = {    key: value for key, value in dist.__dict__.items()     if (        not key.startswith(\'_\') and         not callable(value) and         key not in skip_keys and         key not in dist.display_option_names    )};data[\'metadata\'] = {    k: v for k, v in dist.metadata.__dict__.items()     if k not in (\'license_files\', \'provides_extras\')};sys.stdout.buffer.write(repr(data).encode(\'utf-8\'))']' returned non-zero exit status 1.

Traceback (most recent call last):
  File "<string>", line 1, in <module>
  File "/usr/lib/python3/dist-packages/setuptools/_distutils/core.py", line 267, in run_setup
    exec(code, g)
  File "<string>", line 8, in <module>
ModuleNotFoundError: No module named 'Cython'
[0.959s] ERROR:colcon.colcon_core.package_identification:Exception in package identification extension 'python_setup_py' in 'lib/python3/dist-packages/numpy/core/tests/examples/cython': Command '['/usr/bin/python3', '-c', 'import sys;from contextlib import suppress;exec("with suppress(ImportError):    from setuptools.extern.packaging.specifiers    import SpecifierSet");exec("with suppress(ImportError):    from packaging.specifiers import SpecifierSet");from distutils.core import run_setup;dist = run_setup(    \'setup.py\', script_args=(\'--dry-run\',), stop_after=\'config\');skip_keys = (\'cmdclass\', \'distclass\', \'ext_modules\', \'metadata\');data = {    key: value for key, value in dist.__dict__.items()     if (        not key.startswith(\'_\') and         not callable(value) and         key not in skip_keys and         key not in dist.display_option_names    )};data[\'metadata\'] = {    k: v for k, v in dist.metadata.__dict__.items()     if k not in (\'license_files\', \'provides_extras\')};sys.stdout.buffer.write(repr(data).encode(\'utf-8\'))']' returned non-zero exit status 1.
Traceback (most recent call last):
  File "/usr/lib/python3/dist-packages/colcon_core/package_identification/__init__.py", line 144, in _identify
    retval = extension.identify(_reused_descriptor_instance)
             ^^^^^^^^^^^^^^^^^^^^^^^^^^^^^^^^^^^^^^^^^^^^^^^
  File "/usr/lib/python3/dist-packages/colcon_python_setup_py/package_identification/python_setup_py.py", line 48, in identify
    config = get_setup_information(setup_py)
             ^^^^^^^^^^^^^^^^^^^^^^^^^^^^^^^
  File "/usr/lib/python3/dist-packages/colcon_python_setup_py/package_identification/python_setup_py.py", line 249, in get_setup_information
    _setup_information_cache[hashable_env] = _get_setup_information(
                                             ^^^^^^^^^^^^^^^^^^^^^^^
  File "/usr/lib/python3/dist-packages/colcon_python_setup_py/package_identification/python_setup_py.py", line 296, in _get_setup_information
    result = subprocess.run(
             ^^^^^^^^^^^^^^^
  File "/usr/lib/python3.12/subprocess.py", line 571, in run
    raise CalledProcessError(retcode, process.args,
subprocess.CalledProcessError: Command '['/usr/bin/python3', '-c', 'import sys;from contextlib import suppress;exec("with suppress(ImportError):    from setuptools.extern.packaging.specifiers    import SpecifierSet");exec("with suppress(ImportError):    from packaging.specifiers import SpecifierSet");from distutils.core import run_setup;dist = run_setup(    \'setup.py\', script_args=(\'--dry-run\',), stop_after=\'config\');skip_keys = (\'cmdclass\', \'distclass\', \'ext_modules\', \'metadata\');data = {    key: value for key, value in dist.__dict__.items()     if (        not key.startswith(\'_\') and         not callable(value) and         key not in skip_keys and         key not in dist.display_option_names    )};data[\'metadata\'] = {    k: v for k, v in dist.metadata.__dict__.items()     if k not in (\'license_files\', \'provides_extras\')};sys.stdout.buffer.write(repr(data).encode(\'utf-8\'))']' returned non-zero exit status 1.

[1.134s] ERROR:colcon.colcon_core.package_identification:Failed to determine Python package name in 'lib/python3/dist-packages/numpy/core/tests/examples/limited_api'
[1.134s] ERROR:colcon.colcon_core.package_identification:Exception in package identification extension 'python_setup_py' in 'lib/python3/dist-packages/numpy/core/tests/examples/limited_api': Failed to determine Python package name in 'lib/python3/dist-packages/numpy/core/tests/examples/limited_api'
Traceback (most recent call last):
  File "/usr/lib/python3/dist-packages/colcon_core/package_identification/__init__.py", line 144, in _identify
    retval = extension.identify(_reused_descriptor_instance)
             ^^^^^^^^^^^^^^^^^^^^^^^^^^^^^^^^^^^^^^^^^^^^^^^
  File "/usr/lib/python3/dist-packages/colcon_python_setup_py/package_identification/python_setup_py.py", line 57, in identify
    raise RuntimeError(
RuntimeError: Failed to determine Python package name in 'lib/python3/dist-packages/numpy/core/tests/examples/limited_api'

Traceback (most recent call last):
  File "<string>", line 1, in <module>
  File "/usr/lib/python3/dist-packages/setuptools/_distutils/core.py", line 267, in run_setup
    exec(code, g)
  File "<string>", line 19, in <module>
ModuleNotFoundError: No module named 'numpy.distutils'
[1.281s] ERROR:colcon.colcon_core.package_identification:Exception in package identification extension 'python_setup_py' in 'lib/python3/dist-packages/numpy/f2py': Command '['/usr/bin/python3', '-c', 'import sys;from contextlib import suppress;exec("with suppress(ImportError):    from setuptools.extern.packaging.specifiers    import SpecifierSet");exec("with suppress(ImportError):    from packaging.specifiers import SpecifierSet");from distutils.core import run_setup;dist = run_setup(    \'setup.py\', script_args=(\'--dry-run\',), stop_after=\'config\');skip_keys = (\'cmdclass\', \'distclass\', \'ext_modules\', \'metadata\');data = {    key: value for key, value in dist.__dict__.items()     if (        not key.startswith(\'_\') and         not callable(value) and         key not in skip_keys and         key not in dist.display_option_names    )};data[\'metadata\'] = {    k: v for k, v in dist.metadata.__dict__.items()     if k not in (\'license_files\', \'provides_extras\')};sys.stdout.buffer.write(repr(data).encode(\'utf-8\'))']' returned non-zero exit status 1.
Traceback (most recent call last):
  File "/usr/lib/python3/dist-packages/colcon_core/package_identification/__init__.py", line 144, in _identify
    retval = extension.identify(_reused_descriptor_instance)
             ^^^^^^^^^^^^^^^^^^^^^^^^^^^^^^^^^^^^^^^^^^^^^^^
  File "/usr/lib/python3/dist-packages/colcon_python_setup_py/package_identification/python_setup_py.py", line 48, in identify
    config = get_setup_information(setup_py)
             ^^^^^^^^^^^^^^^^^^^^^^^^^^^^^^^
  File "/usr/lib/python3/dist-packages/colcon_python_setup_py/package_identification/python_setup_py.py", line 249, in get_setup_information
    _setup_information_cache[hashable_env] = _get_setup_information(
                                             ^^^^^^^^^^^^^^^^^^^^^^^
  File "/usr/lib/python3/dist-packages/colcon_python_setup_py/package_identification/python_setup_py.py", line 296, in _get_setup_information
    result = subprocess.run(
             ^^^^^^^^^^^^^^^
  File "/usr/lib/python3.12/subprocess.py", line 571, in run
    raise CalledProcessError(retcode, process.args,
subprocess.CalledProcessError: Command '['/usr/bin/python3', '-c', 'import sys;from contextlib import suppress;exec("with suppress(ImportError):    from setuptools.extern.packaging.specifiers    import SpecifierSet");exec("with suppress(ImportError):    from packaging.specifiers import SpecifierSet");from distutils.core import run_setup;dist = run_setup(    \'setup.py\', script_args=(\'--dry-run\',), stop_after=\'config\');skip_keys = (\'cmdclass\', \'distclass\', \'ext_modules\', \'metadata\');data = {    key: value for key, value in dist.__dict__.items()     if (        not key.startswith(\'_\') and         not callable(value) and         key not in skip_keys and         key not in dist.display_option_names    )};data[\'metadata\'] = {    k: v for k, v in dist.metadata.__dict__.items()     if k not in (\'license_files\', \'provides_extras\')};sys.stdout.buffer.write(repr(data).encode(\'utf-8\'))']' returned non-zero exit status 1.

Traceback (most recent call last):
  File "<string>", line 1, in <module>
  File "/usr/lib/python3/dist-packages/setuptools/_distutils/core.py", line 267, in run_setup
    exec(code, g)
  File "<string>", line 11, in <module>
ModuleNotFoundError: No module named 'numpy.distutils'
[1.439s] ERROR:colcon.colcon_core.package_identification:Exception in package identification extension 'python_setup_py' in 'lib/python3/dist-packages/numpy/lib': Command '['/usr/bin/python3', '-c', 'import sys;from contextlib import suppress;exec("with suppress(ImportError):    from setuptools.extern.packaging.specifiers    import SpecifierSet");exec("with suppress(ImportError):    from packaging.specifiers import SpecifierSet");from distutils.core import run_setup;dist = run_setup(    \'setup.py\', script_args=(\'--dry-run\',), stop_after=\'config\');skip_keys = (\'cmdclass\', \'distclass\', \'ext_modules\', \'metadata\');data = {    key: value for key, value in dist.__dict__.items()     if (        not key.startswith(\'_\') and         not callable(value) and         key not in skip_keys and         key not in dist.display_option_names    )};data[\'metadata\'] = {    k: v for k, v in dist.metadata.__dict__.items()     if k not in (\'license_files\', \'provides_extras\')};sys.stdout.buffer.write(repr(data).encode(\'utf-8\'))']' returned non-zero exit status 1.
Traceback (most recent call last):
  File "/usr/lib/python3/dist-packages/colcon_core/package_identification/__init__.py", line 144, in _identify
    retval = extension.identify(_reused_descriptor_instance)
             ^^^^^^^^^^^^^^^^^^^^^^^^^^^^^^^^^^^^^^^^^^^^^^^
  File "/usr/lib/python3/dist-packages/colcon_python_setup_py/package_identification/python_setup_py.py", line 48, in identify
    config = get_setup_information(setup_py)
             ^^^^^^^^^^^^^^^^^^^^^^^^^^^^^^^
  File "/usr/lib/python3/dist-packages/colcon_python_setup_py/package_identification/python_setup_py.py", line 249, in get_setup_information
    _setup_information_cache[hashable_env] = _get_setup_information(
                                             ^^^^^^^^^^^^^^^^^^^^^^^
  File "/usr/lib/python3/dist-packages/colcon_python_setup_py/package_identification/python_setup_py.py", line 296, in _get_setup_information
    result = subprocess.run(
             ^^^^^^^^^^^^^^^
  File "/usr/lib/python3.12/subprocess.py", line 571, in run
    raise CalledProcessError(retcode, process.args,
subprocess.CalledProcessError: Command '['/usr/bin/python3', '-c', 'import sys;from contextlib import suppress;exec("with suppress(ImportError):    from setuptools.extern.packaging.specifiers    import SpecifierSet");exec("with suppress(ImportError):    from packaging.specifiers import SpecifierSet");from distutils.core import run_setup;dist = run_setup(    \'setup.py\', script_args=(\'--dry-run\',), stop_after=\'config\');skip_keys = (\'cmdclass\', \'distclass\', \'ext_modules\', \'metadata\');data = {    key: value for key, value in dist.__dict__.items()     if (        not key.startswith(\'_\') and         not callable(value) and         key not in skip_keys and         key not in dist.display_option_names    )};data[\'metadata\'] = {    k: v for k, v in dist.metadata.__dict__.items()     if k not in (\'license_files\', \'provides_extras\')};sys.stdout.buffer.write(repr(data).encode(\'utf-8\'))']' returned non-zero exit status 1.

Traceback (most recent call last):
  File "<string>", line 1, in <module>
  File "/usr/lib/python3/dist-packages/setuptools/_distutils/core.py", line 267, in run_setup
    exec(code, g)
  File "<string>", line 10, in <module>
ModuleNotFoundError: No module named 'numpy.distutils'
[1.584s] ERROR:colcon.colcon_core.package_identification:Exception in package identification extension 'python_setup_py' in 'lib/python3/dist-packages/numpy/ma': Command '['/usr/bin/python3', '-c', 'import sys;from contextlib import suppress;exec("with suppress(ImportError):    from setuptools.extern.packaging.specifiers    import SpecifierSet");exec("with suppress(ImportError):    from packaging.specifiers import SpecifierSet");from distutils.core import run_setup;dist = run_setup(    \'setup.py\', script_args=(\'--dry-run\',), stop_after=\'config\');skip_keys = (\'cmdclass\', \'distclass\', \'ext_modules\', \'metadata\');data = {    key: value for key, value in dist.__dict__.items()     if (        not key.startswith(\'_\') and         not callable(value) and         key not in skip_keys and         key not in dist.display_option_names    )};data[\'metadata\'] = {    k: v for k, v in dist.metadata.__dict__.items()     if k not in (\'license_files\', \'provides_extras\')};sys.stdout.buffer.write(repr(data).encode(\'utf-8\'))']' returned non-zero exit status 1.
Traceback (most recent call last):
  File "/usr/lib/python3/dist-packages/colcon_core/package_identification/__init__.py", line 144, in _identify
    retval = extension.identify(_reused_descriptor_instance)
             ^^^^^^^^^^^^^^^^^^^^^^^^^^^^^^^^^^^^^^^^^^^^^^^
  File "/usr/lib/python3/dist-packages/colcon_python_setup_py/package_identification/python_setup_py.py", line 48, in identify
    config = get_setup_information(setup_py)
             ^^^^^^^^^^^^^^^^^^^^^^^^^^^^^^^
  File "/usr/lib/python3/dist-packages/colcon_python_setup_py/package_identification/python_setup_py.py", line 249, in get_setup_information
    _setup_information_cache[hashable_env] = _get_setup_information(
                                             ^^^^^^^^^^^^^^^^^^^^^^^
  File "/usr/lib/python3/dist-packages/colcon_python_setup_py/package_identification/python_setup_py.py", line 296, in _get_setup_information
    result = subprocess.run(
             ^^^^^^^^^^^^^^^
  File "/usr/lib/python3.12/subprocess.py", line 571, in run
    raise CalledProcessError(retcode, process.args,
subprocess.CalledProcessError: Command '['/usr/bin/python3', '-c', 'import sys;from contextlib import suppress;exec("with suppress(ImportError):    from setuptools.extern.packaging.specifiers    import SpecifierSet");exec("with suppress(ImportError):    from packaging.specifiers import SpecifierSet");from distutils.core import run_setup;dist = run_setup(    \'setup.py\', script_args=(\'--dry-run\',), stop_after=\'config\');skip_keys = (\'cmdclass\', \'distclass\', \'ext_modules\', \'metadata\');data = {    key: value for key, value in dist.__dict__.items()     if (        not key.startswith(\'_\') and         not callable(value) and         key not in skip_keys and         key not in dist.display_option_names    )};data[\'metadata\'] = {    k: v for k, v in dist.metadata.__dict__.items()     if k not in (\'license_files\', \'provides_extras\')};sys.stdout.buffer.write(repr(data).encode(\'utf-8\'))']' returned non-zero exit status 1.

Traceback (most recent call last):
  File "<string>", line 1, in <module>
  File "/usr/lib/python3/dist-packages/setuptools/_distutils/core.py", line 267, in run_setup
    exec(code, g)
  File "<string>", line 10, in <module>
ModuleNotFoundError: No module named 'numpy.distutils'
[1.729s] ERROR:colcon.colcon_core.package_identification:Exception in package identification extension 'python_setup_py' in 'lib/python3/dist-packages/numpy/matrixlib': Command '['/usr/bin/python3', '-c', 'import sys;from contextlib import suppress;exec("with suppress(ImportError):    from setuptools.extern.packaging.specifiers    import SpecifierSet");exec("with suppress(ImportError):    from packaging.specifiers import SpecifierSet");from distutils.core import run_setup;dist = run_setup(    \'setup.py\', script_args=(\'--dry-run\',), stop_after=\'config\');skip_keys = (\'cmdclass\', \'distclass\', \'ext_modules\', \'metadata\');data = {    key: value for key, value in dist.__dict__.items()     if (        not key.startswith(\'_\') and         not callable(value) and         key not in skip_keys and         key not in dist.display_option_names    )};data[\'metadata\'] = {    k: v for k, v in dist.metadata.__dict__.items()     if k not in (\'license_files\', \'provides_extras\')};sys.stdout.buffer.write(repr(data).encode(\'utf-8\'))']' returned non-zero exit status 1.
Traceback (most recent call last):
  File "/usr/lib/python3/dist-packages/colcon_core/package_identification/__init__.py", line 144, in _identify
    retval = extension.identify(_reused_descriptor_instance)
             ^^^^^^^^^^^^^^^^^^^^^^^^^^^^^^^^^^^^^^^^^^^^^^^
  File "/usr/lib/python3/dist-packages/colcon_python_setup_py/package_identification/python_setup_py.py", line 48, in identify
    config = get_setup_information(setup_py)
             ^^^^^^^^^^^^^^^^^^^^^^^^^^^^^^^
  File "/usr/lib/python3/dist-packages/colcon_python_setup_py/package_identification/python_setup_py.py", line 249, in get_setup_information
    _setup_information_cache[hashable_env] = _get_setup_information(
                                             ^^^^^^^^^^^^^^^^^^^^^^^
  File "/usr/lib/python3/dist-packages/colcon_python_setup_py/package_identification/python_setup_py.py", line 296, in _get_setup_information
    result = subprocess.run(
             ^^^^^^^^^^^^^^^
  File "/usr/lib/python3.12/subprocess.py", line 571, in run
    raise CalledProcessError(retcode, process.args,
subprocess.CalledProcessError: Command '['/usr/bin/python3', '-c', 'import sys;from contextlib import suppress;exec("with suppress(ImportError):    from setuptools.extern.packaging.specifiers    import SpecifierSet");exec("with suppress(ImportError):    from packaging.specifiers import SpecifierSet");from distutils.core import run_setup;dist = run_setup(    \'setup.py\', script_args=(\'--dry-run\',), stop_after=\'config\');skip_keys = (\'cmdclass\', \'distclass\', \'ext_modules\', \'metadata\');data = {    key: value for key, value in dist.__dict__.items()     if (        not key.startswith(\'_\') and         not callable(value) and         key not in skip_keys and         key not in dist.display_option_names    )};data[\'metadata\'] = {    k: v for k, v in dist.metadata.__dict__.items()     if k not in (\'license_files\', \'provides_extras\')};sys.stdout.buffer.write(repr(data).encode(\'utf-8\'))']' returned non-zero exit status 1.

Traceback (most recent call last):
  File "<string>", line 1, in <module>
  File "/usr/lib/python3/dist-packages/setuptools/_distutils/core.py", line 267, in run_setup
    exec(code, g)
  File "<string>", line 9, in <module>
ModuleNotFoundError: No module named 'numpy.distutils'
[1.872s] ERROR:colcon.colcon_core.package_identification:Exception in package identification extension 'python_setup_py' in 'lib/python3/dist-packages/numpy/polynomial': Command '['/usr/bin/python3', '-c', 'import sys;from contextlib import suppress;exec("with suppress(ImportError):    from setuptools.extern.packaging.specifiers    import SpecifierSet");exec("with suppress(ImportError):    from packaging.specifiers import SpecifierSet");from distutils.core import run_setup;dist = run_setup(    \'setup.py\', script_args=(\'--dry-run\',), stop_after=\'config\');skip_keys = (\'cmdclass\', \'distclass\', \'ext_modules\', \'metadata\');data = {    key: value for key, value in dist.__dict__.items()     if (        not key.startswith(\'_\') and         not callable(value) and         key not in skip_keys and         key not in dist.display_option_names    )};data[\'metadata\'] = {    k: v for k, v in dist.metadata.__dict__.items()     if k not in (\'license_files\', \'provides_extras\')};sys.stdout.buffer.write(repr(data).encode(\'utf-8\'))']' returned non-zero exit status 1.
Traceback (most recent call last):
  File "/usr/lib/python3/dist-packages/colcon_core/package_identification/__init__.py", line 144, in _identify
    retval = extension.identify(_reused_descriptor_instance)
             ^^^^^^^^^^^^^^^^^^^^^^^^^^^^^^^^^^^^^^^^^^^^^^^
  File "/usr/lib/python3/dist-packages/colcon_python_setup_py/package_identification/python_setup_py.py", line 48, in identify
    config = get_setup_information(setup_py)
             ^^^^^^^^^^^^^^^^^^^^^^^^^^^^^^^
  File "/usr/lib/python3/dist-packages/colcon_python_setup_py/package_identification/python_setup_py.py", line 249, in get_setup_information
    _setup_information_cache[hashable_env] = _get_setup_information(
                                             ^^^^^^^^^^^^^^^^^^^^^^^
  File "/usr/lib/python3/dist-packages/colcon_python_setup_py/package_identification/python_setup_py.py", line 296, in _get_setup_information
    result = subprocess.run(
             ^^^^^^^^^^^^^^^
  File "/usr/lib/python3.12/subprocess.py", line 571, in run
    raise CalledProcessError(retcode, process.args,
subprocess.CalledProcessError: Command '['/usr/bin/python3', '-c', 'import sys;from contextlib import suppress;exec("with suppress(ImportError):    from setuptools.extern.packaging.specifiers    import SpecifierSet");exec("with suppress(ImportError):    from packaging.specifiers import SpecifierSet");from distutils.core import run_setup;dist = run_setup(    \'setup.py\', script_args=(\'--dry-run\',), stop_after=\'config\');skip_keys = (\'cmdclass\', \'distclass\', \'ext_modules\', \'metadata\');data = {    key: value for key, value in dist.__dict__.items()     if (        not key.startswith(\'_\') and         not callable(value) and         key not in skip_keys and         key not in dist.display_option_names    )};data[\'metadata\'] = {    k: v for k, v in dist.metadata.__dict__.items()     if k not in (\'license_files\', \'provides_extras\')};sys.stdout.buffer.write(repr(data).encode(\'utf-8\'))']' returned non-zero exit status 1.

Traceback (most recent call last):
  File "<string>", line 1, in <module>
  File "/usr/lib/python3/dist-packages/setuptools/_distutils/core.py", line 267, in run_setup
    exec(code, g)
  File "<string>", line 14, in <module>
ModuleNotFoundError: No module named 'numpy.distutils'
[2.022s] ERROR:colcon.colcon_core.package_identification:Exception in package identification extension 'python_setup_py' in 'lib/python3/dist-packages/numpy/testing': Command '['/usr/bin/python3', '-c', 'import sys;from contextlib import suppress;exec("with suppress(ImportError):    from setuptools.extern.packaging.specifiers    import SpecifierSet");exec("with suppress(ImportError):    from packaging.specifiers import SpecifierSet");from distutils.core import run_setup;dist = run_setup(    \'setup.py\', script_args=(\'--dry-run\',), stop_after=\'config\');skip_keys = (\'cmdclass\', \'distclass\', \'ext_modules\', \'metadata\');data = {    key: value for key, value in dist.__dict__.items()     if (        not key.startswith(\'_\') and         not callable(value) and         key not in skip_keys and         key not in dist.display_option_names    )};data[\'metadata\'] = {    k: v for k, v in dist.metadata.__dict__.items()     if k not in (\'license_files\', \'provides_extras\')};sys.stdout.buffer.write(repr(data).encode(\'utf-8\'))']' returned non-zero exit status 1.
Traceback (most recent call last):
  File "/usr/lib/python3/dist-packages/colcon_core/package_identification/__init__.py", line 144, in _identify
    retval = extension.identify(_reused_descriptor_instance)
             ^^^^^^^^^^^^^^^^^^^^^^^^^^^^^^^^^^^^^^^^^^^^^^^
  File "/usr/lib/python3/dist-packages/colcon_python_setup_py/package_identification/python_setup_py.py", line 48, in identify
    config = get_setup_information(setup_py)
             ^^^^^^^^^^^^^^^^^^^^^^^^^^^^^^^
  File "/usr/lib/python3/dist-packages/colcon_python_setup_py/package_identification/python_setup_py.py", line 249, in get_setup_information
    _setup_information_cache[hashable_env] = _get_setup_information(
                                             ^^^^^^^^^^^^^^^^^^^^^^^
  File "/usr/lib/python3/dist-packages/colcon_python_setup_py/package_identification/python_setup_py.py", line 296, in _get_setup_information
    result = subprocess.run(
             ^^^^^^^^^^^^^^^
  File "/usr/lib/python3.12/subprocess.py", line 571, in run
    raise CalledProcessError(retcode, process.args,
subprocess.CalledProcessError: Command '['/usr/bin/python3', '-c', 'import sys;from contextlib import suppress;exec("with suppress(ImportError):    from setuptools.extern.packaging.specifiers    import SpecifierSet");exec("with suppress(ImportError):    from packaging.specifiers import SpecifierSet");from distutils.core import run_setup;dist = run_setup(    \'setup.py\', script_args=(\'--dry-run\',), stop_after=\'config\');skip_keys = (\'cmdclass\', \'distclass\', \'ext_modules\', \'metadata\');data = {    key: value for key, value in dist.__dict__.items()     if (        not key.startswith(\'_\') and         not callable(value) and         key not in skip_keys and         key not in dist.display_option_names    )};data[\'metadata\'] = {    k: v for k, v in dist.metadata.__dict__.items()     if k not in (\'license_files\', \'provides_extras\')};sys.stdout.buffer.write(repr(data).encode(\'utf-8\'))']' returned non-zero exit status 1.

Traceback (most recent call last):
  File "<string>", line 1, in <module>
  File "/usr/lib/python3/dist-packages/setuptools/_distutils/core.py", line 267, in run_setup
    exec(code, g)
  File "<string>", line 10, in <module>
ModuleNotFoundError: No module named 'numpy.distutils'
[2.167s] ERROR:colcon.colcon_core.package_identification:Exception in package identification extension 'python_setup_py' in 'lib/python3/dist-packages/numpy/typing': Command '['/usr/bin/python3', '-c', 'import sys;from contextlib import suppress;exec("with suppress(ImportError):    from setuptools.extern.packaging.specifiers    import SpecifierSet");exec("with suppress(ImportError):    from packaging.specifiers import SpecifierSet");from distutils.core import run_setup;dist = run_setup(    \'setup.py\', script_args=(\'--dry-run\',), stop_after=\'config\');skip_keys = (\'cmdclass\', \'distclass\', \'ext_modules\', \'metadata\');data = {    key: value for key, value in dist.__dict__.items()     if (        not key.startswith(\'_\') and         not callable(value) and         key not in skip_keys and         key not in dist.display_option_names    )};data[\'metadata\'] = {    k: v for k, v in dist.metadata.__dict__.items()     if k not in (\'license_files\', \'provides_extras\')};sys.stdout.buffer.write(repr(data).encode(\'utf-8\'))']' returned non-zero exit status 1.
Traceback (most recent call last):
  File "/usr/lib/python3/dist-packages/colcon_core/package_identification/__init__.py", line 144, in _identify
    retval = extension.identify(_reused_descriptor_instance)
             ^^^^^^^^^^^^^^^^^^^^^^^^^^^^^^^^^^^^^^^^^^^^^^^
  File "/usr/lib/python3/dist-packages/colcon_python_setup_py/package_identification/python_setup_py.py", line 48, in identify
    config = get_setup_information(setup_py)
             ^^^^^^^^^^^^^^^^^^^^^^^^^^^^^^^
  File "/usr/lib/python3/dist-packages/colcon_python_setup_py/package_identification/python_setup_py.py", line 249, in get_setup_information
    _setup_information_cache[hashable_env] = _get_setup_information(
                                             ^^^^^^^^^^^^^^^^^^^^^^^
  File "/usr/lib/python3/dist-packages/colcon_python_setup_py/package_identification/python_setup_py.py", line 296, in _get_setup_information
    result = subprocess.run(
             ^^^^^^^^^^^^^^^
  File "/usr/lib/python3.12/subprocess.py", line 571, in run
    raise CalledProcessError(retcode, process.args,
subprocess.CalledProcessError: Command '['/usr/bin/python3', '-c', 'import sys;from contextlib import suppress;exec("with suppress(ImportError):    from setuptools.extern.packaging.specifiers    import SpecifierSet");exec("with suppress(ImportError):    from packaging.specifiers import SpecifierSet");from distutils.core import run_setup;dist = run_setup(    \'setup.py\', script_args=(\'--dry-run\',), stop_after=\'config\');skip_keys = (\'cmdclass\', \'distclass\', \'ext_modules\', \'metadata\');data = {    key: value for key, value in dist.__dict__.items()     if (        not key.startswith(\'_\') and         not callable(value) and         key not in skip_keys and         key not in dist.display_option_names    )};data[\'metadata\'] = {    k: v for k, v in dist.metadata.__dict__.items()     if k not in (\'license_files\', \'provides_extras\')};sys.stdout.buffer.write(repr(data).encode(\'utf-8\'))']' returned non-zero exit status 1.

Traceback (most recent call last):
  File "<string>", line 1, in <module>
  File "/usr/lib/python3/dist-packages/setuptools/_distutils/core.py", line 267, in run_setup
    exec(code, g)
  File "<string>", line 11, in <module>
ImportError: attempted relative import with no known parent package
[2.411s] ERROR:colcon.colcon_core.package_identification:Exception in package identification extension 'python_setup_py' in 'lib/python3.12/test/libregrtest': Command '['/usr/bin/python3', '-c', 'import sys;from contextlib import suppress;exec("with suppress(ImportError):    from setuptools.extern.packaging.specifiers    import SpecifierSet");exec("with suppress(ImportError):    from packaging.specifiers import SpecifierSet");from distutils.core import run_setup;dist = run_setup(    \'setup.py\', script_args=(\'--dry-run\',), stop_after=\'config\');skip_keys = (\'cmdclass\', \'distclass\', \'ext_modules\', \'metadata\');data = {    key: value for key, value in dist.__dict__.items()     if (        not key.startswith(\'_\') and         not callable(value) and         key not in skip_keys and         key not in dist.display_option_names    )};data[\'metadata\'] = {    k: v for k, v in dist.metadata.__dict__.items()     if k not in (\'license_files\', \'provides_extras\')};sys.stdout.buffer.write(repr(data).encode(\'utf-8\'))']' returned non-zero exit status 1.
Traceback (most recent call last):
  File "/usr/lib/python3/dist-packages/colcon_core/package_identification/__init__.py", line 144, in _identify
    retval = extension.identify(_reused_descriptor_instance)
             ^^^^^^^^^^^^^^^^^^^^^^^^^^^^^^^^^^^^^^^^^^^^^^^
  File "/usr/lib/python3/dist-packages/colcon_python_setup_py/package_identification/python_setup_py.py", line 48, in identify
    config = get_setup_information(setup_py)
             ^^^^^^^^^^^^^^^^^^^^^^^^^^^^^^^
  File "/usr/lib/python3/dist-packages/colcon_python_setup_py/package_identification/python_setup_py.py", line 249, in get_setup_information
    _setup_information_cache[hashable_env] = _get_setup_information(
                                             ^^^^^^^^^^^^^^^^^^^^^^^
  File "/usr/lib/python3/dist-packages/colcon_python_setup_py/package_identification/python_setup_py.py", line 296, in _get_setup_information
    result = subprocess.run(
             ^^^^^^^^^^^^^^^
  File "/usr/lib/python3.12/subprocess.py", line 571, in run
    raise CalledProcessError(retcode, process.args,
subprocess.CalledProcessError: Command '['/usr/bin/python3', '-c', 'import sys;from contextlib import suppress;exec("with suppress(ImportError):    from setuptools.extern.packaging.specifiers    import SpecifierSet");exec("with suppress(ImportError):    from packaging.specifiers import SpecifierSet");from distutils.core import run_setup;dist = run_setup(    \'setup.py\', script_args=(\'--dry-run\',), stop_after=\'config\');skip_keys = (\'cmdclass\', \'distclass\', \'ext_modules\', \'metadata\');data = {    key: value for key, value in dist.__dict__.items()     if (        not key.startswith(\'_\') and         not callable(value) and         key not in skip_keys and         key not in dist.display_option_names    )};data[\'metadata\'] = {    k: v for k, v in dist.metadata.__dict__.items()     if k not in (\'license_files\', \'provides_extras\')};sys.stdout.buffer.write(repr(data).encode(\'utf-8\'))']' returned non-zero exit status 1.